[2024-10-28T22:20:14.562+0000] {local_task_job_runner.py:123} INFO - ::group::Pre task execution logs
[2024-10-28T22:20:14.585+0000] {taskinstance.py:2612} INFO - Dependencies all met for dep_context=non-requeueable deps ti=<TaskInstance: indices_provincias_v01.inflacion_santafe scheduled__2024-10-27T00:00:00+00:00 [queued]>
[2024-10-28T22:20:14.597+0000] {taskinstance.py:2612} INFO - Dependencies all met for dep_context=requeueable deps ti=<TaskInstance: indices_provincias_v01.inflacion_santafe scheduled__2024-10-27T00:00:00+00:00 [queued]>
[2024-10-28T22:20:14.598+0000] {taskinstance.py:2865} INFO - Starting attempt 2 of 7
[2024-10-28T22:20:14.614+0000] {taskinstance.py:2888} INFO - Executing <Task(PythonOperator): inflacion_santafe> on 2024-10-27 00:00:00+00:00
[2024-10-28T22:20:14.623+0000] {standard_task_runner.py:104} INFO - Running: ['***', 'tasks', 'run', 'indices_provincias_v01', 'inflacion_santafe', 'scheduled__2024-10-27T00:00:00+00:00', '--job-id', '240', '--raw', '--subdir', 'DAGS_FOLDER/second_dag.py', '--cfg-path', '/tmp/tmps_7r2m0t']
[2024-10-28T22:20:14.626+0000] {standard_task_runner.py:105} INFO - Job 240: Subtask inflacion_santafe
[2024-10-28T22:20:14.629+0000] {logging_mixin.py:190} WARNING - /home/***/.local/lib/python3.12/site-packages/***/task/task_runner/standard_task_runner.py:70 DeprecationWarning: This process (pid=4602) is multi-threaded, use of fork() may lead to deadlocks in the child.
[2024-10-28T22:20:14.629+0000] {standard_task_runner.py:72} INFO - Started process 4603 to run task
[2024-10-28T22:20:14.682+0000] {task_command.py:467} INFO - Running <TaskInstance: indices_provincias_v01.inflacion_santafe scheduled__2024-10-27T00:00:00+00:00 [running]> on host 276004bbea2b
[2024-10-28T22:20:14.932+0000] {taskinstance.py:3131} INFO - Exporting env vars: AIRFLOW_CTX_DAG_OWNER='rolo' AIRFLOW_CTX_DAG_ID='indices_provincias_v01' AIRFLOW_CTX_TASK_ID='inflacion_santafe' AIRFLOW_CTX_EXECUTION_DATE='2024-10-27T00:00:00+00:00' AIRFLOW_CTX_TRY_NUMBER='2' AIRFLOW_CTX_DAG_RUN_ID='scheduled__2024-10-27T00:00:00+00:00'
[2024-10-28T22:20:14.933+0000] {taskinstance.py:731} INFO - ::endgroup::
[2024-10-28T22:20:24.806+0000] {local_task_job_runner.py:346} WARNING - State of this instance has been externally set to restarting. Terminating instance.
[2024-10-28T22:20:24.807+0000] {local_task_job_runner.py:245} INFO - ::endgroup::
[2024-10-28T22:20:24.819+0000] {process_utils.py:132} INFO - Sending 15 to group 4603. PIDs of all processes in the group: [4605, 4603]
[2024-10-28T22:20:24.820+0000] {process_utils.py:87} INFO - Sending the signal 15 to group 4603
[2024-10-28T22:20:24.820+0000] {taskinstance.py:3092} ERROR - Received SIGTERM. Terminating subprocesses.
[2024-10-28T22:20:25.675+0000] {clientserver.py:538} INFO - Error while receiving.
Traceback (most recent call last):
  File "/opt/airflow/functions/indicators_province_functions.py", line 85, in santafe_inflation
    data_inflacion_general = spark.read.csv(INDICE_JOINED, header=True)
                             ^^^^^^^^^^^^^^^^^^^^^^^^^^^^^^^^^^^^^^^^^^
  File "/home/airflow/.local/lib/python3.12/site-packages/pyspark/sql/readwriter.py", line 740, in csv
    return self._df(self._jreader.csv(self._spark._sc._jvm.PythonUtils.toSeq(path)))
                    ^^^^^^^^^^^^^^^^^^^^^^^^^^^^^^^^^^^^^^^^^^^^^^^^^^^^^^^^^^^^^^^
  File "/home/airflow/.local/lib/python3.12/site-packages/py4j/java_gateway.py", line 1321, in __call__
    answer = self.gateway_client.send_command(command)
             ^^^^^^^^^^^^^^^^^^^^^^^^^^^^^^^^^^^^^^^^^
  File "/home/airflow/.local/lib/python3.12/site-packages/py4j/java_gateway.py", line 1038, in send_command
    response = connection.send_command(command)
               ^^^^^^^^^^^^^^^^^^^^^^^^^^^^^^^^
  File "/home/airflow/.local/lib/python3.12/site-packages/py4j/clientserver.py", line 511, in send_command
    answer = smart_decode(self.stream.readline()[:-1])
                          ^^^^^^^^^^^^^^^^^^^^^^
  File "/usr/local/lib/python3.12/socket.py", line 720, in readinto
    return self._sock.recv_into(b)
           ^^^^^^^^^^^^^^^^^^^^^^^
  File "/home/airflow/.local/lib/python3.12/site-packages/airflow/models/taskinstance.py", line 3094, in signal_handler
    raise AirflowTaskTerminated("Task received SIGTERM signal")
airflow.exceptions.AirflowTaskTerminated: Task received SIGTERM signal

During handling of the above exception, another exception occurred:

Traceback (most recent call last):
  File "/home/airflow/.local/lib/python3.12/site-packages/py4j/clientserver.py", line 511, in send_command
    answer = smart_decode(self.stream.readline()[:-1])
                          ^^^^^^^^^^^^^^^^^^^^^^
  File "/usr/local/lib/python3.12/socket.py", line 720, in readinto
    return self._sock.recv_into(b)
           ^^^^^^^^^^^^^^^^^^^^^^^
ConnectionResetError: [Errno 104] Connection reset by peer
[2024-10-28T22:20:25.700+0000] {clientserver.py:543} INFO - Closing down clientserver connection
[2024-10-28T22:20:25.707+0000] {java_gateway.py:1055} ERROR - Exception while sending command.
Traceback (most recent call last):
  File "/opt/airflow/functions/indicators_province_functions.py", line 85, in santafe_inflation
    data_inflacion_general = spark.read.csv(INDICE_JOINED, header=True)
                             ^^^^^^^^^^^^^^^^^^^^^^^^^^^^^^^^^^^^^^^^^^
  File "/home/airflow/.local/lib/python3.12/site-packages/pyspark/sql/readwriter.py", line 740, in csv
    return self._df(self._jreader.csv(self._spark._sc._jvm.PythonUtils.toSeq(path)))
                    ^^^^^^^^^^^^^^^^^^^^^^^^^^^^^^^^^^^^^^^^^^^^^^^^^^^^^^^^^^^^^^^
  File "/home/airflow/.local/lib/python3.12/site-packages/py4j/java_gateway.py", line 1321, in __call__
    answer = self.gateway_client.send_command(command)
             ^^^^^^^^^^^^^^^^^^^^^^^^^^^^^^^^^^^^^^^^^
  File "/home/airflow/.local/lib/python3.12/site-packages/py4j/java_gateway.py", line 1038, in send_command
    response = connection.send_command(command)
               ^^^^^^^^^^^^^^^^^^^^^^^^^^^^^^^^
  File "/home/airflow/.local/lib/python3.12/site-packages/py4j/clientserver.py", line 511, in send_command
    answer = smart_decode(self.stream.readline()[:-1])
                          ^^^^^^^^^^^^^^^^^^^^^^
  File "/usr/local/lib/python3.12/socket.py", line 720, in readinto
    return self._sock.recv_into(b)
           ^^^^^^^^^^^^^^^^^^^^^^^
  File "/home/airflow/.local/lib/python3.12/site-packages/airflow/models/taskinstance.py", line 3094, in signal_handler
    raise AirflowTaskTerminated("Task received SIGTERM signal")
airflow.exceptions.AirflowTaskTerminated: Task received SIGTERM signal

During handling of the above exception, another exception occurred:

Traceback (most recent call last):
  File "/home/airflow/.local/lib/python3.12/site-packages/py4j/clientserver.py", line 511, in send_command
    answer = smart_decode(self.stream.readline()[:-1])
                          ^^^^^^^^^^^^^^^^^^^^^^
  File "/usr/local/lib/python3.12/socket.py", line 720, in readinto
    return self._sock.recv_into(b)
           ^^^^^^^^^^^^^^^^^^^^^^^
ConnectionResetError: [Errno 104] Connection reset by peer

During handling of the above exception, another exception occurred:

Traceback (most recent call last):
  File "/home/airflow/.local/lib/python3.12/site-packages/py4j/java_gateway.py", line 1038, in send_command
    response = connection.send_command(command)
               ^^^^^^^^^^^^^^^^^^^^^^^^^^^^^^^^
  File "/home/airflow/.local/lib/python3.12/site-packages/py4j/clientserver.py", line 539, in send_command
    raise Py4JNetworkError(
py4j.protocol.Py4JNetworkError: Error while sending or receiving
[2024-10-28T22:20:25.739+0000] {logging_mixin.py:190} WARNING - /home/***/.local/lib/python3.12/site-packages/pyspark/context.py:657 RuntimeWarning: Unable to cleanly shutdown Spark JVM process. It is possible that the process has crashed, been killed or may also be in a zombie state.
[2024-10-28T22:20:25.759+0000] {clientserver.py:538} INFO - Error while receiving.
Traceback (most recent call last):
  File "/home/airflow/.local/lib/python3.12/site-packages/py4j/clientserver.py", line 516, in send_command
    raise Py4JNetworkError("Answer from Java side is empty")
py4j.protocol.Py4JNetworkError: Answer from Java side is empty
[2024-10-28T22:20:25.759+0000] {clientserver.py:543} INFO - Closing down clientserver connection
[2024-10-28T22:20:25.760+0000] {java_gateway.py:1055} ERROR - Exception while sending command.
Traceback (most recent call last):
  File "/home/airflow/.local/lib/python3.12/site-packages/py4j/clientserver.py", line 516, in send_command
    raise Py4JNetworkError("Answer from Java side is empty")
py4j.protocol.Py4JNetworkError: Answer from Java side is empty

During handling of the above exception, another exception occurred:

Traceback (most recent call last):
  File "/home/airflow/.local/lib/python3.12/site-packages/py4j/java_gateway.py", line 1038, in send_command
    response = connection.send_command(command)
               ^^^^^^^^^^^^^^^^^^^^^^^^^^^^^^^^
  File "/home/airflow/.local/lib/python3.12/site-packages/py4j/clientserver.py", line 539, in send_command
    raise Py4JNetworkError(
py4j.protocol.Py4JNetworkError: Error while sending or receiving
[2024-10-28T22:20:25.761+0000] {clientserver.py:543} INFO - Closing down clientserver connection
[2024-10-28T22:20:25.761+0000] {clientserver.py:543} INFO - Closing down clientserver connection
[2024-10-28T22:20:25.762+0000] {clientserver.py:543} INFO - Closing down clientserver connection
[2024-10-28T22:20:25.773+0000] {clientserver.py:543} INFO - Closing down clientserver connection
[2024-10-28T22:20:25.774+0000] {clientserver.py:543} INFO - Closing down clientserver connection
[2024-10-28T22:20:25.774+0000] {clientserver.py:543} INFO - Closing down clientserver connection
[2024-10-28T22:20:25.774+0000] {clientserver.py:543} INFO - Closing down clientserver connection
[2024-10-28T22:20:25.775+0000] {clientserver.py:543} INFO - Closing down clientserver connection
[2024-10-28T22:20:25.775+0000] {clientserver.py:543} INFO - Closing down clientserver connection
[2024-10-28T22:20:25.783+0000] {clientserver.py:543} INFO - Closing down clientserver connection
[2024-10-28T22:20:25.783+0000] {clientserver.py:543} INFO - Closing down clientserver connection
[2024-10-28T22:20:25.783+0000] {clientserver.py:543} INFO - Closing down clientserver connection
[2024-10-28T22:20:25.784+0000] {clientserver.py:543} INFO - Closing down clientserver connection
[2024-10-28T22:20:25.793+0000] {clientserver.py:543} INFO - Closing down clientserver connection
[2024-10-28T22:20:25.793+0000] {clientserver.py:543} INFO - Closing down clientserver connection
[2024-10-28T22:20:25.793+0000] {clientserver.py:543} INFO - Closing down clientserver connection
[2024-10-28T22:20:25.794+0000] {clientserver.py:543} INFO - Closing down clientserver connection
[2024-10-28T22:20:25.794+0000] {clientserver.py:543} INFO - Closing down clientserver connection
[2024-10-28T22:20:25.794+0000] {clientserver.py:543} INFO - Closing down clientserver connection
[2024-10-28T22:20:25.795+0000] {clientserver.py:543} INFO - Closing down clientserver connection
[2024-10-28T22:20:25.795+0000] {clientserver.py:543} INFO - Closing down clientserver connection
[2024-10-28T22:20:25.782+0000] {clientserver.py:543} INFO - Closing down clientserver connection
[2024-10-28T22:20:25.798+0000] {taskinstance.py:3310} ERROR - Task failed with exception
Traceback (most recent call last):
  File "/opt/airflow/functions/indicators_province_functions.py", line 85, in santafe_inflation
    data_inflacion_general = spark.read.csv(INDICE_JOINED, header=True)
                             ^^^^^^^^^^^^^^^^^^^^^^^^^^^^^^^^^^^^^^^^^^
  File "/home/airflow/.local/lib/python3.12/site-packages/pyspark/sql/readwriter.py", line 740, in csv
    return self._df(self._jreader.csv(self._spark._sc._jvm.PythonUtils.toSeq(path)))
                    ^^^^^^^^^^^^^^^^^^^^^^^^^^^^^^^^^^^^^^^^^^^^^^^^^^^^^^^^^^^^^^^
  File "/home/airflow/.local/lib/python3.12/site-packages/py4j/java_gateway.py", line 1321, in __call__
    answer = self.gateway_client.send_command(command)
             ^^^^^^^^^^^^^^^^^^^^^^^^^^^^^^^^^^^^^^^^^
  File "/home/airflow/.local/lib/python3.12/site-packages/py4j/java_gateway.py", line 1038, in send_command
    response = connection.send_command(command)
               ^^^^^^^^^^^^^^^^^^^^^^^^^^^^^^^^
  File "/home/airflow/.local/lib/python3.12/site-packages/py4j/clientserver.py", line 511, in send_command
    answer = smart_decode(self.stream.readline()[:-1])
                          ^^^^^^^^^^^^^^^^^^^^^^
  File "/usr/local/lib/python3.12/socket.py", line 720, in readinto
    return self._sock.recv_into(b)
           ^^^^^^^^^^^^^^^^^^^^^^^
  File "/home/airflow/.local/lib/python3.12/site-packages/airflow/models/taskinstance.py", line 3094, in signal_handler
    raise AirflowTaskTerminated("Task received SIGTERM signal")
airflow.exceptions.AirflowTaskTerminated: Task received SIGTERM signal

During handling of the above exception, another exception occurred:

Traceback (most recent call last):
  File "/home/airflow/.local/lib/python3.12/site-packages/airflow/models/taskinstance.py", line 767, in _execute_task
    result = _execute_callable(context=context, **execute_callable_kwargs)
             ^^^^^^^^^^^^^^^^^^^^^^^^^^^^^^^^^^^^^^^^^^^^^^^^^^^^^^^^^^^^^
  File "/home/airflow/.local/lib/python3.12/site-packages/airflow/models/taskinstance.py", line 733, in _execute_callable
    return ExecutionCallableRunner(
           ^^^^^^^^^^^^^^^^^^^^^^^^
  File "/home/airflow/.local/lib/python3.12/site-packages/airflow/utils/operator_helpers.py", line 252, in run
    return self.func(*args, **kwargs)
           ^^^^^^^^^^^^^^^^^^^^^^^^^^
  File "/home/airflow/.local/lib/python3.12/site-packages/airflow/models/baseoperator.py", line 406, in wrapper
    return func(self, *args, **kwargs)
           ^^^^^^^^^^^^^^^^^^^^^^^^^^^
  File "/home/airflow/.local/lib/python3.12/site-packages/airflow/operators/python.py", line 238, in execute
    return_value = self.execute_callable()
                   ^^^^^^^^^^^^^^^^^^^^^^^
  File "/home/airflow/.local/lib/python3.12/site-packages/airflow/operators/python.py", line 256, in execute_callable
    return runner.run(*self.op_args, **self.op_kwargs)
           ^^^^^^^^^^^^^^^^^^^^^^^^^^^^^^^^^^^^^^^^^^^
  File "/home/airflow/.local/lib/python3.12/site-packages/airflow/utils/operator_helpers.py", line 252, in run
    return self.func(*args, **kwargs)
           ^^^^^^^^^^^^^^^^^^^^^^^^^^
  File "/opt/airflow/functions/indicators_province_functions.py", line 120, in santafe_inflation
    spark.stop()
  File "/home/airflow/.local/lib/python3.12/site-packages/pyspark/sql/session.py", line 1799, in stop
    self._jvm.SparkSession.clearDefaultSession()
    ^^^^^^^^^^^^^^^^^^^^^^
  File "/home/airflow/.local/lib/python3.12/site-packages/py4j/java_gateway.py", line 1712, in __getattr__
    answer = self._gateway_client.send_command(
             ^^^^^^^^^^^^^^^^^^^^^^^^^^^^^^^^^^
  File "/home/airflow/.local/lib/python3.12/site-packages/py4j/java_gateway.py", line 1036, in send_command
    connection = self._get_connection()
                 ^^^^^^^^^^^^^^^^^^^^^^
  File "/home/airflow/.local/lib/python3.12/site-packages/py4j/clientserver.py", line 284, in _get_connection
    connection = self._create_new_connection()
                 ^^^^^^^^^^^^^^^^^^^^^^^^^^^^^
  File "/home/airflow/.local/lib/python3.12/site-packages/py4j/clientserver.py", line 291, in _create_new_connection
    connection.connect_to_java_server()
  File "/home/airflow/.local/lib/python3.12/site-packages/py4j/clientserver.py", line 438, in connect_to_java_server
    self.socket.connect((self.java_address, self.java_port))
ConnectionRefusedError: [Errno 111] Connection refused
[2024-10-28T22:20:25.808+0000] {clientserver.py:543} INFO - Closing down clientserver connection
[2024-10-28T22:20:25.809+0000] {clientserver.py:543} INFO - Closing down clientserver connection
[2024-10-28T22:20:25.809+0000] {clientserver.py:543} INFO - Closing down clientserver connection
[2024-10-28T22:20:25.809+0000] {clientserver.py:543} INFO - Closing down clientserver connection
[2024-10-28T22:20:25.810+0000] {clientserver.py:543} INFO - Closing down clientserver connection
[2024-10-28T22:20:25.810+0000] {clientserver.py:543} INFO - Closing down clientserver connection
[2024-10-28T22:20:25.810+0000] {clientserver.py:543} INFO - Closing down clientserver connection
[2024-10-28T22:20:25.811+0000] {clientserver.py:543} INFO - Closing down clientserver connection
[2024-10-28T22:20:25.811+0000] {clientserver.py:543} INFO - Closing down clientserver connection
[2024-10-28T22:20:25.811+0000] {clientserver.py:543} INFO - Closing down clientserver connection
[2024-10-28T22:20:25.812+0000] {clientserver.py:543} INFO - Closing down clientserver connection
[2024-10-28T22:20:25.824+0000] {clientserver.py:543} INFO - Closing down clientserver connection
[2024-10-28T22:20:25.825+0000] {clientserver.py:543} INFO - Closing down clientserver connection
[2024-10-28T22:20:25.825+0000] {clientserver.py:543} INFO - Closing down clientserver connection
[2024-10-28T22:20:25.827+0000] {clientserver.py:543} INFO - Closing down clientserver connection
[2024-10-28T22:20:25.827+0000] {clientserver.py:543} INFO - Closing down clientserver connection
[2024-10-28T22:20:25.842+0000] {taskinstance.py:1225} INFO - Marking task as UP_FOR_RETRY. dag_id=indices_provincias_v01, task_id=inflacion_santafe, run_id=scheduled__2024-10-27T00:00:00+00:00, execution_date=20241027T000000, start_date=20241028T222014, end_date=20241028T222025
[2024-10-28T22:20:25.929+0000] {taskinstance.py:340} INFO - ::group::Post task execution logs
[2024-10-28T22:20:25.931+0000] {standard_task_runner.py:124} ERROR - Failed to execute job 240 for task inflacion_santafe ([Errno 111] Connection refused; 4603)
Traceback (most recent call last):
  File "/opt/airflow/functions/indicators_province_functions.py", line 85, in santafe_inflation
    data_inflacion_general = spark.read.csv(INDICE_JOINED, header=True)
                             ^^^^^^^^^^^^^^^^^^^^^^^^^^^^^^^^^^^^^^^^^^
  File "/home/airflow/.local/lib/python3.12/site-packages/pyspark/sql/readwriter.py", line 740, in csv
    return self._df(self._jreader.csv(self._spark._sc._jvm.PythonUtils.toSeq(path)))
                    ^^^^^^^^^^^^^^^^^^^^^^^^^^^^^^^^^^^^^^^^^^^^^^^^^^^^^^^^^^^^^^^
  File "/home/airflow/.local/lib/python3.12/site-packages/py4j/java_gateway.py", line 1321, in __call__
    answer = self.gateway_client.send_command(command)
             ^^^^^^^^^^^^^^^^^^^^^^^^^^^^^^^^^^^^^^^^^
  File "/home/airflow/.local/lib/python3.12/site-packages/py4j/java_gateway.py", line 1038, in send_command
    response = connection.send_command(command)
               ^^^^^^^^^^^^^^^^^^^^^^^^^^^^^^^^
  File "/home/airflow/.local/lib/python3.12/site-packages/py4j/clientserver.py", line 511, in send_command
    answer = smart_decode(self.stream.readline()[:-1])
                          ^^^^^^^^^^^^^^^^^^^^^^
  File "/usr/local/lib/python3.12/socket.py", line 720, in readinto
    return self._sock.recv_into(b)
           ^^^^^^^^^^^^^^^^^^^^^^^
  File "/home/airflow/.local/lib/python3.12/site-packages/airflow/models/taskinstance.py", line 3094, in signal_handler
    raise AirflowTaskTerminated("Task received SIGTERM signal")
airflow.exceptions.AirflowTaskTerminated: Task received SIGTERM signal

During handling of the above exception, another exception occurred:

Traceback (most recent call last):
  File "/home/airflow/.local/lib/python3.12/site-packages/airflow/task/task_runner/standard_task_runner.py", line 117, in _start_by_fork
    ret = args.func(args, dag=self.dag)
          ^^^^^^^^^^^^^^^^^^^^^^^^^^^^^
  File "/home/airflow/.local/lib/python3.12/site-packages/airflow/cli/cli_config.py", line 49, in command
    return func(*args, **kwargs)
           ^^^^^^^^^^^^^^^^^^^^^
  File "/home/airflow/.local/lib/python3.12/site-packages/airflow/utils/cli.py", line 115, in wrapper
    return f(*args, **kwargs)
           ^^^^^^^^^^^^^^^^^^
  File "/home/airflow/.local/lib/python3.12/site-packages/airflow/cli/commands/task_command.py", line 483, in task_run
    task_return_code = _run_task_by_selected_method(args, _dag, ti)
                       ^^^^^^^^^^^^^^^^^^^^^^^^^^^^^^^^^^^^^^^^^^^^
  File "/home/airflow/.local/lib/python3.12/site-packages/airflow/cli/commands/task_command.py", line 256, in _run_task_by_selected_method
    return _run_raw_task(args, ti)
           ^^^^^^^^^^^^^^^^^^^^^^^
  File "/home/airflow/.local/lib/python3.12/site-packages/airflow/cli/commands/task_command.py", line 341, in _run_raw_task
    return ti._run_raw_task(
           ^^^^^^^^^^^^^^^^^
  File "/home/airflow/.local/lib/python3.12/site-packages/airflow/utils/session.py", line 97, in wrapper
    return func(*args, session=session, **kwargs)
           ^^^^^^^^^^^^^^^^^^^^^^^^^^^^^^^^^^^^^^
  File "/home/airflow/.local/lib/python3.12/site-packages/airflow/models/taskinstance.py", line 3004, in _run_raw_task
    return _run_raw_task(
           ^^^^^^^^^^^^^^
  File "/home/airflow/.local/lib/python3.12/site-packages/airflow/models/taskinstance.py", line 273, in _run_raw_task
    TaskInstance._execute_task_with_callbacks(
  File "/home/airflow/.local/lib/python3.12/site-packages/airflow/models/taskinstance.py", line 3158, in _execute_task_with_callbacks
    result = self._execute_task(context, task_orig)
             ^^^^^^^^^^^^^^^^^^^^^^^^^^^^^^^^^^^^^^
  File "/home/airflow/.local/lib/python3.12/site-packages/airflow/models/taskinstance.py", line 3182, in _execute_task
    return _execute_task(self, context, task_orig)
           ^^^^^^^^^^^^^^^^^^^^^^^^^^^^^^^^^^^^^^^
  File "/home/airflow/.local/lib/python3.12/site-packages/airflow/models/taskinstance.py", line 767, in _execute_task
    result = _execute_callable(context=context, **execute_callable_kwargs)
             ^^^^^^^^^^^^^^^^^^^^^^^^^^^^^^^^^^^^^^^^^^^^^^^^^^^^^^^^^^^^^
  File "/home/airflow/.local/lib/python3.12/site-packages/airflow/models/taskinstance.py", line 733, in _execute_callable
    return ExecutionCallableRunner(
           ^^^^^^^^^^^^^^^^^^^^^^^^
  File "/home/airflow/.local/lib/python3.12/site-packages/airflow/utils/operator_helpers.py", line 252, in run
    return self.func(*args, **kwargs)
           ^^^^^^^^^^^^^^^^^^^^^^^^^^
  File "/home/airflow/.local/lib/python3.12/site-packages/airflow/models/baseoperator.py", line 406, in wrapper
    return func(self, *args, **kwargs)
           ^^^^^^^^^^^^^^^^^^^^^^^^^^^
  File "/home/airflow/.local/lib/python3.12/site-packages/airflow/operators/python.py", line 238, in execute
    return_value = self.execute_callable()
                   ^^^^^^^^^^^^^^^^^^^^^^^
  File "/home/airflow/.local/lib/python3.12/site-packages/airflow/operators/python.py", line 256, in execute_callable
    return runner.run(*self.op_args, **self.op_kwargs)
           ^^^^^^^^^^^^^^^^^^^^^^^^^^^^^^^^^^^^^^^^^^^
  File "/home/airflow/.local/lib/python3.12/site-packages/airflow/utils/operator_helpers.py", line 252, in run
    return self.func(*args, **kwargs)
           ^^^^^^^^^^^^^^^^^^^^^^^^^^
  File "/opt/airflow/functions/indicators_province_functions.py", line 120, in santafe_inflation
    spark.stop()
  File "/home/airflow/.local/lib/python3.12/site-packages/pyspark/sql/session.py", line 1799, in stop
    self._jvm.SparkSession.clearDefaultSession()
    ^^^^^^^^^^^^^^^^^^^^^^
  File "/home/airflow/.local/lib/python3.12/site-packages/py4j/java_gateway.py", line 1712, in __getattr__
    answer = self._gateway_client.send_command(
             ^^^^^^^^^^^^^^^^^^^^^^^^^^^^^^^^^^
  File "/home/airflow/.local/lib/python3.12/site-packages/py4j/java_gateway.py", line 1036, in send_command
    connection = self._get_connection()
                 ^^^^^^^^^^^^^^^^^^^^^^
  File "/home/airflow/.local/lib/python3.12/site-packages/py4j/clientserver.py", line 284, in _get_connection
    connection = self._create_new_connection()
                 ^^^^^^^^^^^^^^^^^^^^^^^^^^^^^
  File "/home/airflow/.local/lib/python3.12/site-packages/py4j/clientserver.py", line 291, in _create_new_connection
    connection.connect_to_java_server()
  File "/home/airflow/.local/lib/python3.12/site-packages/py4j/clientserver.py", line 438, in connect_to_java_server
    self.socket.connect((self.java_address, self.java_port))
ConnectionRefusedError: [Errno 111] Connection refused
[2024-10-28T22:20:26.006+0000] {process_utils.py:80} INFO - Process psutil.Process(pid=4603, status='terminated', exitcode=1, started='22:20:14') (4603) terminated with exit code 1
[2024-10-28T22:20:26.007+0000] {process_utils.py:80} INFO - Process psutil.Process(pid=4605, status='terminated', started='22:20:14') (4605) terminated with exit code None
